2024-11-07 10:19:29,473 WARNING:Running in DEBUG MODE. Sensitive information may be logged.
2024-11-07 10:19:35,144 ERROR:Unexpected error during data transmission
Traceback (most recent call last):
  File "C:\Users\David.Peter\Downloads\Softwares & Drivers\Scripts\System monitoring\agent.py", line 257, in send_data_to_server
    ssl_context = ssl.create_default_context()
                  ^^^
NameError: name 'ssl' is not defined. Did you forget to import 'ssl'
2024-11-07 10:19:37,099 ERROR:Error sending data to SharePoint
Traceback (most recent call last):
  File "C:\Users\David.Peter\AppData\Local\Programs\Python\Python312\Lib\site-packages\msal\authority.py", line 79, in __init__
    openid_config = tenant_discovery(
                    ^^^^^^^^^^^^^^^^^
  File "C:\Users\David.Peter\AppData\Local\Programs\Python\Python312\Lib\site-packages\msal\authority.py", line 216, in tenant_discovery
    raise ValueError("OIDC Discovery failed on {}. HTTP status: {}, Error: {}".format(
ValueError: OIDC Discovery failed on https://login.microsoftonline.com/your_tenant_id/v2.0/.well-known/openid-configuration. HTTP status: 400, Error: {"error":"invalid_tenant","error_description":"AADSTS90002: Tenant 'your_tenant_id' not found. Check to make sure you have the correct tenant ID and are signing into the correct cloud. Check with your subscription administrator, this may happen if there are no active subscriptions for the tenant. Trace ID: 33e268e7-8d81-4523-ae99-5bae3188ec00 Correlation ID: d68a6850-6cf7-476d-b276-b99ae36e4074 Timestamp: 2024-11-07 07:19:37Z","error_codes":[90002],"timestamp":"2024-11-07 07:19:37Z","trace_id":"33e268e7-8d81-4523-ae99-5bae3188ec00","correlation_id":"d68a6850-6cf7-476d-b276-b99ae36e4074","error_uri":"https://login.microsoftonline.com/error?code=90002"}

During handling of the above exception, another exception occurred:

Traceback (most recent call last):
  File "C:\Users\David.Peter\Downloads\Softwares & Drivers\Scripts\System monitoring\agent.py", line 280, in send_data_to_sharepoint
    app = ConfidentialClientApplication(
          ^^^^^^^^^^^^^^^^^^^^^^^^^^^^^^
  File "C:\Users\David.Peter\AppData\Local\Programs\Python\Python312\Lib\site-packages\msal\application.py", line 608, in __init__
    self.authority = Authority(
                     ^^^^^^^^^^
  File "C:\Users\David.Peter\AppData\Local\Programs\Python\Python312\Lib\site-packages\msal\authority.py", line 95, in __init__
    raise ValueError(error_message)
ValueError: Unable to get authority configuration for https://login.microsoftonline.com/your_tenant_id. Authority would typically be in a format of https://login.microsoftonline.com/your_tenant or https://tenant_name.ciamlogin.com or https://tenant_name.b2clogin.com/tenant.onmicrosoft.com/policy.  Also please double check your tenant name or GUID is correct.
2024-11-07 10:19:50,106 ERROR:Unexpected error during data transmission
Traceback (most recent call last):
  File "C:\Users\David.Peter\Downloads\Softwares & Drivers\Scripts\System monitoring\agent.py", line 257, in send_data_to_server
    ssl_context = ssl.create_default_context()
                  ^^^
NameError: name 'ssl' is not defined. Did you forget to import 'ssl'
2024-11-07 10:19:51,185 ERROR:Error sending data to SharePoint
Traceback (most recent call last):
  File "C:\Users\David.Peter\AppData\Local\Programs\Python\Python312\Lib\site-packages\msal\authority.py", line 79, in __init__
    openid_config = tenant_discovery(
                    ^^^^^^^^^^^^^^^^^
  File "C:\Users\David.Peter\AppData\Local\Programs\Python\Python312\Lib\site-packages\msal\authority.py", line 216, in tenant_discovery
    raise ValueError("OIDC Discovery failed on {}. HTTP status: {}, Error: {}".format(
ValueError: OIDC Discovery failed on https://login.microsoftonline.com/your_tenant_id/v2.0/.well-known/openid-configuration. HTTP status: 400, Error: {"error":"invalid_tenant","error_description":"AADSTS90002: Tenant 'your_tenant_id' not found. Check to make sure you have the correct tenant ID and are signing into the correct cloud. Check with your subscription administrator, this may happen if there are no active subscriptions for the tenant. Trace ID: 88e54b42-51c1-44ff-8692-b0b146d5dd00 Correlation ID: 8c3e8539-5220-4c17-a95a-ad308b6c70e4 Timestamp: 2024-11-07 07:19:51Z","error_codes":[90002],"timestamp":"2024-11-07 07:19:51Z","trace_id":"88e54b42-51c1-44ff-8692-b0b146d5dd00","correlation_id":"8c3e8539-5220-4c17-a95a-ad308b6c70e4","error_uri":"https://login.microsoftonline.com/error?code=90002"}

During handling of the above exception, another exception occurred:

Traceback (most recent call last):
  File "C:\Users\David.Peter\Downloads\Softwares & Drivers\Scripts\System monitoring\agent.py", line 280, in send_data_to_sharepoint
    app = ConfidentialClientApplication(
          ^^^^^^^^^^^^^^^^^^^^^^^^^^^^^^
  File "C:\Users\David.Peter\AppData\Local\Programs\Python\Python312\Lib\site-packages\msal\application.py", line 608, in __init__
    self.authority = Authority(
                     ^^^^^^^^^^
  File "C:\Users\David.Peter\AppData\Local\Programs\Python\Python312\Lib\site-packages\msal\authority.py", line 95, in __init__
    raise ValueError(error_message)
ValueError: Unable to get authority configuration for https://login.microsoftonline.com/your_tenant_id. Authority would typically be in a format of https://login.microsoftonline.com/your_tenant or https://tenant_name.ciamlogin.com or https://tenant_name.b2clogin.com/tenant.onmicrosoft.com/policy.  Also please double check your tenant name or GUID is correct.
2024-11-07 10:19:56,839 INFO:Received signal to terminate. Shutting down gracefully...
2024-11-07 10:19:56,842 INFO:Clinic server monitor shut down
2024-11-08 15:53:36,611 WARNING:Running in DEBUG MODE. Sensitive information may be logged.
2024-11-08 15:53:44,916 ERROR:Error sending data to SharePoint
Traceback (most recent call last):
  File "C:\Users\David.Peter\AppData\Local\Programs\Python\Python312\Lib\site-packages\msal\authority.py", line 79, in __init__
    openid_config = tenant_discovery(
                    ^^^^^^^^^^^^^^^^^
  File "C:\Users\David.Peter\AppData\Local\Programs\Python\Python312\Lib\site-packages\msal\authority.py", line 216, in tenant_discovery
    raise ValueError("OIDC Discovery failed on {}. HTTP status: {}, Error: {}".format(
ValueError: OIDC Discovery failed on https://login.microsoftonline.com/your_tenant_id/v2.0/.well-known/openid-configuration. HTTP status: 400, Error: {"error":"invalid_tenant","error_description":"AADSTS90002: Tenant 'your_tenant_id' not found. Check to make sure you have the correct tenant ID and are signing into the correct cloud. Check with your subscription administrator, this may happen if there are no active subscriptions for the tenant. Trace ID: 7b826be2-d775-4f56-bf7e-41503cd26600 Correlation ID: e5581493-54a4-4132-8d85-659fa65f159e Timestamp: 2024-11-08 12:53:44Z","error_codes":[90002],"timestamp":"2024-11-08 12:53:44Z","trace_id":"7b826be2-d775-4f56-bf7e-41503cd26600","correlation_id":"e5581493-54a4-4132-8d85-659fa65f159e","error_uri":"https://login.microsoftonline.com/error?code=90002"}

During handling of the above exception, another exception occurred:

Traceback (most recent call last):
  File "C:\Users\David.Peter\Downloads\Softwares & Drivers\Scripts\System monitoring\agent.py", line 281, in send_data_to_sharepoint
    app = ConfidentialClientApplication(
          ^^^^^^^^^^^^^^^^^^^^^^^^^^^^^^
  File "C:\Users\David.Peter\AppData\Local\Programs\Python\Python312\Lib\site-packages\msal\application.py", line 608, in __init__
    self.authority = Authority(
                     ^^^^^^^^^^
  File "C:\Users\David.Peter\AppData\Local\Programs\Python\Python312\Lib\site-packages\msal\authority.py", line 95, in __init__
    raise ValueError(error_message)
ValueError: Unable to get authority configuration for https://login.microsoftonline.com/your_tenant_id. Authority would typically be in a format of https://login.microsoftonline.com/your_tenant or https://tenant_name.ciamlogin.com or https://tenant_name.b2clogin.com/tenant.onmicrosoft.com/policy.  Also please double check your tenant name or GUID is correct.
2024-11-08 15:53:46,470 ERROR:Error sending data to server: [Errno None] Can not write request body for https://your-server-url.com/api. Retry 1/3 in 1.50 seconds
2024-11-08 15:53:48,386 ERROR:Error sending data to server: Cannot connect to host your-server-url.com:443 ssl:<ssl.SSLContext object at 0x0000020CF2E099D0> [An established connection was aborted by the software in your host machine]. Retry 2/3 in 2.25 seconds
2024-11-08 15:53:51,313 ERROR:Error sending data to server: Cannot connect to host your-server-url.com:443 ssl:<ssl.SSLContext object at 0x0000020CF3092E50> [An established connection was aborted by the software in your host machine]. Retry 3/3 in 3.38 seconds
2024-11-08 15:53:54,693 CRITICAL:Max retries reached. Failed to send data
2024-11-08 15:54:13,894 INFO:Received signal to terminate. Shutting down gracefully...
2024-11-08 15:54:14,030 ERROR:Error sending data to SharePoint
Traceback (most recent call last):
  File "C:\Users\David.Peter\AppData\Local\Programs\Python\Python312\Lib\site-packages\msal\authority.py", line 79, in __init__
    openid_config = tenant_discovery(
                    ^^^^^^^^^^^^^^^^^
  File "C:\Users\David.Peter\AppData\Local\Programs\Python\Python312\Lib\site-packages\msal\authority.py", line 216, in tenant_discovery
    raise ValueError("OIDC Discovery failed on {}. HTTP status: {}, Error: {}".format(
ValueError: OIDC Discovery failed on https://login.microsoftonline.com/your_tenant_id/v2.0/.well-known/openid-configuration. HTTP status: 400, Error: {"error":"invalid_tenant","error_description":"AADSTS90002: Tenant 'your_tenant_id' not found. Check to make sure you have the correct tenant ID and are signing into the correct cloud. Check with your subscription administrator, this may happen if there are no active subscriptions for the tenant. Trace ID: 817b2c6c-2b5b-480d-b82b-e1324e0b7700 Correlation ID: 0f9f3a8c-e409-4b61-b1a3-c1f73119f28e Timestamp: 2024-11-08 12:54:14Z","error_codes":[90002],"timestamp":"2024-11-08 12:54:14Z","trace_id":"817b2c6c-2b5b-480d-b82b-e1324e0b7700","correlation_id":"0f9f3a8c-e409-4b61-b1a3-c1f73119f28e","error_uri":"https://login.microsoftonline.com/error?code=90002"}

During handling of the above exception, another exception occurred:

Traceback (most recent call last):
  File "C:\Users\David.Peter\Downloads\Softwares & Drivers\Scripts\System monitoring\agent.py", line 281, in send_data_to_sharepoint
    app = ConfidentialClientApplication(
          ^^^^^^^^^^^^^^^^^^^^^^^^^^^^^^
  File "C:\Users\David.Peter\AppData\Local\Programs\Python\Python312\Lib\site-packages\msal\application.py", line 608, in __init__
    self.authority = Authority(
                     ^^^^^^^^^^
  File "C:\Users\David.Peter\AppData\Local\Programs\Python\Python312\Lib\site-packages\msal\authority.py", line 95, in __init__
    raise ValueError(error_message)
ValueError: Unable to get authority configuration for https://login.microsoftonline.com/your_tenant_id. Authority would typically be in a format of https://login.microsoftonline.com/your_tenant or https://tenant_name.ciamlogin.com or https://tenant_name.b2clogin.com/tenant.onmicrosoft.com/policy.  Also please double check your tenant name or GUID is correct.
2024-11-08 15:54:14,045 ERROR:An error occurred while running the main loop
Traceback (most recent call last):
  File "C:\Users\David.Peter\Downloads\Softwares & Drivers\Scripts\System monitoring\agent.py", line 394, in <module>
    asyncio.run(main_loop())
  File "C:\Users\David.Peter\AppData\Local\Programs\Python\Python312\Lib\asyncio\runners.py", line 194, in run
    return runner.run(main)
           ^^^^^^^^^^^^^^^^
  File "C:\Users\David.Peter\AppData\Local\Programs\Python\Python312\Lib\asyncio\runners.py", line 118, in run
    return self._loop.run_until_complete(task)
           ^^^^^^^^^^^^^^^^^^^^^^^^^^^^^^^^^^^
  File "C:\Users\David.Peter\AppData\Local\Programs\Python\Python312\Lib\asyncio\base_events.py", line 685, in run_until_complete
    raise RuntimeError('Event loop stopped before Future completed.')
RuntimeError: Event loop stopped before Future completed.
2024-11-08 15:54:14,062 INFO:Clinic server monitor shut down
2024-11-11 10:10:58,333 WARNING:Running in DEBUG MODE. Sensitive information may be logged.
2024-11-11 10:11:05,662 ERROR:Error sending data to SharePoint
Traceback (most recent call last):
  File "c:\Users\David.Peter\Downloads\Softwares & Drivers\Scripts\System monitoring\venv\Lib\site-packages\msal\authority.py", line 79, in __init__
    openid_config = tenant_discovery(
                    ^^^^^^^^^^^^^^^^^
  File "c:\Users\David.Peter\Downloads\Softwares & Drivers\Scripts\System monitoring\venv\Lib\site-packages\msal\authority.py", line 216, in tenant_discovery
    raise ValueError("OIDC Discovery failed on {}. HTTP status: {}, Error: {}".format(
ValueError: OIDC Discovery failed on https://login.microsoftonline.com/your_tenant_id/v2.0/.well-known/openid-configuration. HTTP status: 400, Error: {"error":"invalid_tenant","error_description":"AADSTS90002: Tenant 'your_tenant_id' not found. Check to make sure you have the correct tenant ID and are signing into the correct cloud. Check with your subscription administrator, this may happen if there are no active subscriptions for the tenant. Trace ID: 7e1374de-8e5b-45a7-a708-852a2d16d300 Correlation ID: d2b9ba86-a287-48ea-9ccc-531ec821b69e Timestamp: 2024-11-11 07:11:05Z","error_codes":[90002],"timestamp":"2024-11-11 07:11:05Z","trace_id":"7e1374de-8e5b-45a7-a708-852a2d16d300","correlation_id":"d2b9ba86-a287-48ea-9ccc-531ec821b69e","error_uri":"https://login.microsoftonline.com/error?code=90002"}

During handling of the above exception, another exception occurred:

Traceback (most recent call last):
  File "C:\Users\David.Peter\Downloads\Softwares & Drivers\Scripts\System monitoring\agent.py", line 281, in send_data_to_sharepoint
    app = ConfidentialClientApplication(
          ^^^^^^^^^^^^^^^^^^^^^^^^^^^^^^
  File "c:\Users\David.Peter\Downloads\Softwares & Drivers\Scripts\System monitoring\venv\Lib\site-packages\msal\application.py", line 608, in __init__
    self.authority = Authority(
                     ^^^^^^^^^^
  File "c:\Users\David.Peter\Downloads\Softwares & Drivers\Scripts\System monitoring\venv\Lib\site-packages\msal\authority.py", line 95, in __init__
    raise ValueError(error_message)
ValueError: Unable to get authority configuration for https://login.microsoftonline.com/your_tenant_id. Authority would typically be in a format of https://login.microsoftonline.com/your_tenant or https://tenant_name.ciamlogin.com or https://tenant_name.b2clogin.com/tenant.onmicrosoft.com/policy.  Also please double check your tenant name or GUID is correct.
2024-11-11 10:11:08,341 ERROR:Error sending data to server: [WinError 10053] An established connection was aborted by the software in your host machine. Retry 1/3 in 1.50 seconds
2024-11-11 10:11:10,378 ERROR:Error sending data to server: Cannot connect to host your-server-url.com:443 ssl:<ssl.SSLContext object at 0x000001664F7CC750> [An established connection was aborted by the software in your host machine]. Retry 2/3 in 2.25 seconds
2024-11-11 10:11:13,010 ERROR:Error sending data to server: Cannot connect to host your-server-url.com:443 ssl:<ssl.SSLContext object at 0x000001664F7CCAD0> [An established connection was aborted by the software in your host machine]. Retry 3/3 in 3.38 seconds
2024-11-11 10:11:16,388 CRITICAL:Max retries reached. Failed to send data
2024-11-11 10:11:29,769 ERROR:Error sending data to SharePoint
Traceback (most recent call last):
  File "c:\Users\David.Peter\Downloads\Softwares & Drivers\Scripts\System monitoring\venv\Lib\site-packages\msal\authority.py", line 79, in __init__
    openid_config = tenant_discovery(
                    ^^^^^^^^^^^^^^^^^
  File "c:\Users\David.Peter\Downloads\Softwares & Drivers\Scripts\System monitoring\venv\Lib\site-packages\msal\authority.py", line 216, in tenant_discovery
    raise ValueError("OIDC Discovery failed on {}. HTTP status: {}, Error: {}".format(
ValueError: OIDC Discovery failed on https://login.microsoftonline.com/your_tenant_id/v2.0/.well-known/openid-configuration. HTTP status: 400, Error: {"error":"invalid_tenant","error_description":"AADSTS90002: Tenant 'your_tenant_id' not found. Check to make sure you have the correct tenant ID and are signing into the correct cloud. Check with your subscription administrator, this may happen if there are no active subscriptions for the tenant. Trace ID: cfd05e55-f84b-4d13-8b4b-6d31b5ee5301 Correlation ID: 4000099c-df8e-452e-9e99-b27f250ce52e Timestamp: 2024-11-11 07:11:29Z","error_codes":[90002],"timestamp":"2024-11-11 07:11:29Z","trace_id":"cfd05e55-f84b-4d13-8b4b-6d31b5ee5301","correlation_id":"4000099c-df8e-452e-9e99-b27f250ce52e","error_uri":"https://login.microsoftonline.com/error?code=90002"}

During handling of the above exception, another exception occurred:

Traceback (most recent call last):
  File "C:\Users\David.Peter\Downloads\Softwares & Drivers\Scripts\System monitoring\agent.py", line 281, in send_data_to_sharepoint
    app = ConfidentialClientApplication(
          ^^^^^^^^^^^^^^^^^^^^^^^^^^^^^^
  File "c:\Users\David.Peter\Downloads\Softwares & Drivers\Scripts\System monitoring\venv\Lib\site-packages\msal\application.py", line 608, in __init__
    self.authority = Authority(
                     ^^^^^^^^^^
  File "c:\Users\David.Peter\Downloads\Softwares & Drivers\Scripts\System monitoring\venv\Lib\site-packages\msal\authority.py", line 95, in __init__
    raise ValueError(error_message)
ValueError: Unable to get authority configuration for https://login.microsoftonline.com/your_tenant_id. Authority would typically be in a format of https://login.microsoftonline.com/your_tenant or https://tenant_name.ciamlogin.com or https://tenant_name.b2clogin.com/tenant.onmicrosoft.com/policy.  Also please double check your tenant name or GUID is correct.
2024-11-11 10:11:30,047 ERROR:Error sending data to server: Cannot connect to host your-server-url.com:443 ssl:<ssl.SSLContext object at 0x000001664F825950> [An established connection was aborted by the software in your host machine]. Retry 1/3 in 1.50 seconds
2024-11-11 10:11:31,949 ERROR:Error sending data to server: Cannot connect to host your-server-url.com:443 ssl:<ssl.SSLContext object at 0x000001664F826950> [An established connection was aborted by the software in your host machine]. Retry 2/3 in 2.25 seconds
2024-11-11 10:11:34,744 ERROR:Error sending data to server: Cannot connect to host your-server-url.com:443 ssl:<ssl.SSLContext object at 0x000001664F826D50> [An established connection was aborted by the software in your host machine]. Retry 3/3 in 3.38 seconds
2024-11-11 10:11:38,126 CRITICAL:Max retries reached. Failed to send data
2024-11-11 10:11:51,540 ERROR:Error sending data to SharePoint
Traceback (most recent call last):
  File "c:\Users\David.Peter\Downloads\Softwares & Drivers\Scripts\System monitoring\venv\Lib\site-packages\msal\authority.py", line 79, in __init__
    openid_config = tenant_discovery(
                    ^^^^^^^^^^^^^^^^^
  File "c:\Users\David.Peter\Downloads\Softwares & Drivers\Scripts\System monitoring\venv\Lib\site-packages\msal\authority.py", line 216, in tenant_discovery
    raise ValueError("OIDC Discovery failed on {}. HTTP status: {}, Error: {}".format(
ValueError: OIDC Discovery failed on https://login.microsoftonline.com/your_tenant_id/v2.0/.well-known/openid-configuration. HTTP status: 400, Error: {"error":"invalid_tenant","error_description":"AADSTS90002: Tenant 'your_tenant_id' not found. Check to make sure you have the correct tenant ID and are signing into the correct cloud. Check with your subscription administrator, this may happen if there are no active subscriptions for the tenant. Trace ID: 7e7875ad-1172-42b0-9adc-fd51c0d18901 Correlation ID: 0ad444af-6d96-4b1e-acdc-f48dc07a6a9c Timestamp: 2024-11-11 07:11:51Z","error_codes":[90002],"timestamp":"2024-11-11 07:11:51Z","trace_id":"7e7875ad-1172-42b0-9adc-fd51c0d18901","correlation_id":"0ad444af-6d96-4b1e-acdc-f48dc07a6a9c","error_uri":"https://login.microsoftonline.com/error?code=90002"}

During handling of the above exception, another exception occurred:

Traceback (most recent call last):
  File "C:\Users\David.Peter\Downloads\Softwares & Drivers\Scripts\System monitoring\agent.py", line 281, in send_data_to_sharepoint
    app = ConfidentialClientApplication(
          ^^^^^^^^^^^^^^^^^^^^^^^^^^^^^^
  File "c:\Users\David.Peter\Downloads\Softwares & Drivers\Scripts\System monitoring\venv\Lib\site-packages\msal\application.py", line 608, in __init__
    self.authority = Authority(
                     ^^^^^^^^^^
  File "c:\Users\David.Peter\Downloads\Softwares & Drivers\Scripts\System monitoring\venv\Lib\site-packages\msal\authority.py", line 95, in __init__
    raise ValueError(error_message)
ValueError: Unable to get authority configuration for https://login.microsoftonline.com/your_tenant_id. Authority would typically be in a format of https://login.microsoftonline.com/your_tenant or https://tenant_name.ciamlogin.com or https://tenant_name.b2clogin.com/tenant.onmicrosoft.com/policy.  Also please double check your tenant name or GUID is correct.
2024-11-11 10:11:51,947 ERROR:Error sending data to server: Cannot connect to host your-server-url.com:443 ssl:<ssl.SSLContext object at 0x000001664F825750> [An established connection was aborted by the software in your host machine]. Retry 1/3 in 1.50 seconds
2024-11-11 10:11:53,834 ERROR:Error sending data to server: Cannot connect to host your-server-url.com:443 ssl:<ssl.SSLContext object at 0x000001664F827650> [An established connection was aborted by the software in your host machine]. Retry 2/3 in 2.25 seconds
2024-11-11 10:11:56,529 ERROR:Error sending data to server: Cannot connect to host your-server-url.com:443 ssl:<ssl.SSLContext object at 0x000001664F8542D0> [An established connection was aborted by the software in your host machine]. Retry 3/3 in 3.38 seconds
2024-11-11 10:11:59,917 CRITICAL:Max retries reached. Failed to send data
2024-11-11 10:12:13,455 ERROR:Error sending data to SharePoint
Traceback (most recent call last):
  File "c:\Users\David.Peter\Downloads\Softwares & Drivers\Scripts\System monitoring\venv\Lib\site-packages\msal\authority.py", line 79, in __init__
    openid_config = tenant_discovery(
                    ^^^^^^^^^^^^^^^^^
  File "c:\Users\David.Peter\Downloads\Softwares & Drivers\Scripts\System monitoring\venv\Lib\site-packages\msal\authority.py", line 216, in tenant_discovery
    raise ValueError("OIDC Discovery failed on {}. HTTP status: {}, Error: {}".format(
ValueError: OIDC Discovery failed on https://login.microsoftonline.com/your_tenant_id/v2.0/.well-known/openid-configuration. HTTP status: 400, Error: {"error":"invalid_tenant","error_description":"AADSTS90002: Tenant 'your_tenant_id' not found. Check to make sure you have the correct tenant ID and are signing into the correct cloud. Check with your subscription administrator, this may happen if there are no active subscriptions for the tenant. Trace ID: 49219679-0599-4d71-beb0-e67fc957cd01 Correlation ID: a46e73af-c63d-4834-b753-3a199750af26 Timestamp: 2024-11-11 07:12:13Z","error_codes":[90002],"timestamp":"2024-11-11 07:12:13Z","trace_id":"49219679-0599-4d71-beb0-e67fc957cd01","correlation_id":"a46e73af-c63d-4834-b753-3a199750af26","error_uri":"https://login.microsoftonline.com/error?code=90002"}

During handling of the above exception, another exception occurred:

Traceback (most recent call last):
  File "C:\Users\David.Peter\Downloads\Softwares & Drivers\Scripts\System monitoring\agent.py", line 281, in send_data_to_sharepoint
    app = ConfidentialClientApplication(
          ^^^^^^^^^^^^^^^^^^^^^^^^^^^^^^
  File "c:\Users\David.Peter\Downloads\Softwares & Drivers\Scripts\System monitoring\venv\Lib\site-packages\msal\application.py", line 608, in __init__
    self.authority = Authority(
                     ^^^^^^^^^^
  File "c:\Users\David.Peter\Downloads\Softwares & Drivers\Scripts\System monitoring\venv\Lib\site-packages\msal\authority.py", line 95, in __init__
    raise ValueError(error_message)
ValueError: Unable to get authority configuration for https://login.microsoftonline.com/your_tenant_id. Authority would typically be in a format of https://login.microsoftonline.com/your_tenant or https://tenant_name.ciamlogin.com or https://tenant_name.b2clogin.com/tenant.onmicrosoft.com/policy.  Also please double check your tenant name or GUID is correct.
2024-11-11 10:12:14,066 ERROR:Error sending data to server: Cannot connect to host your-server-url.com:443 ssl:<ssl.SSLContext object at 0x000001664F827650> [An established connection was aborted by the software in your host machine]. Retry 1/3 in 1.50 seconds
2024-11-11 10:12:16,117 ERROR:Error sending data to server: Cannot connect to host your-server-url.com:443 ssl:<ssl.SSLContext object at 0x000001664F825950> [An established connection was aborted by the software in your host machine]. Retry 2/3 in 2.25 seconds
2024-11-11 10:12:18,776 ERROR:Error sending data to server: Cannot connect to host your-server-url.com:443 ssl:<ssl.SSLContext object at 0x000001664F827450> [An established connection was aborted by the software in your host machine]. Retry 3/3 in 3.38 seconds
2024-11-11 10:12:22,166 CRITICAL:Max retries reached. Failed to send data
2024-11-11 10:12:35,777 ERROR:Error sending data to SharePoint
Traceback (most recent call last):
  File "c:\Users\David.Peter\Downloads\Softwares & Drivers\Scripts\System monitoring\venv\Lib\site-packages\msal\authority.py", line 79, in __init__
    openid_config = tenant_discovery(
                    ^^^^^^^^^^^^^^^^^
  File "c:\Users\David.Peter\Downloads\Softwares & Drivers\Scripts\System monitoring\venv\Lib\site-packages\msal\authority.py", line 216, in tenant_discovery
    raise ValueError("OIDC Discovery failed on {}. HTTP status: {}, Error: {}".format(
ValueError: OIDC Discovery failed on https://login.microsoftonline.com/your_tenant_id/v2.0/.well-known/openid-configuration. HTTP status: 400, Error: {"error":"invalid_tenant","error_description":"AADSTS90002: Tenant 'your_tenant_id' not found. Check to make sure you have the correct tenant ID and are signing into the correct cloud. Check with your subscription administrator, this may happen if there are no active subscriptions for the tenant. Trace ID: 35662d15-0c28-41a4-8e3b-ece730f7e200 Correlation ID: 6d339d0d-17b7-40ef-b517-208358e2bcab Timestamp: 2024-11-11 07:12:35Z","error_codes":[90002],"timestamp":"2024-11-11 07:12:35Z","trace_id":"35662d15-0c28-41a4-8e3b-ece730f7e200","correlation_id":"6d339d0d-17b7-40ef-b517-208358e2bcab","error_uri":"https://login.microsoftonline.com/error?code=90002"}

During handling of the above exception, another exception occurred:

Traceback (most recent call last):
  File "C:\Users\David.Peter\Downloads\Softwares & Drivers\Scripts\System monitoring\agent.py", line 281, in send_data_to_sharepoint
    app = ConfidentialClientApplication(
          ^^^^^^^^^^^^^^^^^^^^^^^^^^^^^^
  File "c:\Users\David.Peter\Downloads\Softwares & Drivers\Scripts\System monitoring\venv\Lib\site-packages\msal\application.py", line 608, in __init__
    self.authority = Authority(
                     ^^^^^^^^^^
  File "c:\Users\David.Peter\Downloads\Softwares & Drivers\Scripts\System monitoring\venv\Lib\site-packages\msal\authority.py", line 95, in __init__
    raise ValueError(error_message)
ValueError: Unable to get authority configuration for https://login.microsoftonline.com/your_tenant_id. Authority would typically be in a format of https://login.microsoftonline.com/your_tenant or https://tenant_name.ciamlogin.com or https://tenant_name.b2clogin.com/tenant.onmicrosoft.com/policy.  Also please double check your tenant name or GUID is correct.
2024-11-11 10:12:36,186 ERROR:Error sending data to server: Cannot connect to host your-server-url.com:443 ssl:<ssl.SSLContext object at 0x000001664F854650> [An established connection was aborted by the software in your host machine]. Retry 1/3 in 1.50 seconds
2024-11-11 10:12:38,168 ERROR:Error sending data to server: Cannot connect to host your-server-url.com:443 ssl:<ssl.SSLContext object at 0x000001664F761850> [An established connection was aborted by the software in your host machine]. Retry 2/3 in 2.25 seconds
2024-11-11 10:12:40,898 ERROR:Error sending data to server: Cannot connect to host your-server-url.com:443 ssl:<ssl.SSLContext object at 0x000001664F825550> [An established connection was aborted by the software in your host machine]. Retry 3/3 in 3.38 seconds
2024-11-11 10:12:44,289 CRITICAL:Max retries reached. Failed to send data
2024-11-11 10:12:58,733 ERROR:Error sending data to SharePoint
Traceback (most recent call last):
  File "c:\Users\David.Peter\Downloads\Softwares & Drivers\Scripts\System monitoring\venv\Lib\site-packages\msal\authority.py", line 79, in __init__
    openid_config = tenant_discovery(
                    ^^^^^^^^^^^^^^^^^
  File "c:\Users\David.Peter\Downloads\Softwares & Drivers\Scripts\System monitoring\venv\Lib\site-packages\msal\authority.py", line 216, in tenant_discovery
    raise ValueError("OIDC Discovery failed on {}. HTTP status: {}, Error: {}".format(
ValueError: OIDC Discovery failed on https://login.microsoftonline.com/your_tenant_id/v2.0/.well-known/openid-configuration. HTTP status: 400, Error: {"error":"invalid_tenant","error_description":"AADSTS90002: Tenant 'your_tenant_id' not found. Check to make sure you have the correct tenant ID and are signing into the correct cloud. Check with your subscription administrator, this may happen if there are no active subscriptions for the tenant. Trace ID: 4d911634-e667-41ba-bbf7-be0f5784f700 Correlation ID: 19df82a9-eccb-498b-b930-a638dc381f61 Timestamp: 2024-11-11 07:12:58Z","error_codes":[90002],"timestamp":"2024-11-11 07:12:58Z","trace_id":"4d911634-e667-41ba-bbf7-be0f5784f700","correlation_id":"19df82a9-eccb-498b-b930-a638dc381f61","error_uri":"https://login.microsoftonline.com/error?code=90002"}

During handling of the above exception, another exception occurred:

Traceback (most recent call last):
  File "C:\Users\David.Peter\Downloads\Softwares & Drivers\Scripts\System monitoring\agent.py", line 281, in send_data_to_sharepoint
    app = ConfidentialClientApplication(
          ^^^^^^^^^^^^^^^^^^^^^^^^^^^^^^
  File "c:\Users\David.Peter\Downloads\Softwares & Drivers\Scripts\System monitoring\venv\Lib\site-packages\msal\application.py", line 608, in __init__
    self.authority = Authority(
                     ^^^^^^^^^^
  File "c:\Users\David.Peter\Downloads\Softwares & Drivers\Scripts\System monitoring\venv\Lib\site-packages\msal\authority.py", line 95, in __init__
    raise ValueError(error_message)
ValueError: Unable to get authority configuration for https://login.microsoftonline.com/your_tenant_id. Authority would typically be in a format of https://login.microsoftonline.com/your_tenant or https://tenant_name.ciamlogin.com or https://tenant_name.b2clogin.com/tenant.onmicrosoft.com/policy.  Also please double check your tenant name or GUID is correct.
2024-11-11 10:12:59,018 ERROR:Error sending data to server: Cannot connect to host your-server-url.com:443 ssl:<ssl.SSLContext object at 0x000001664F827650> [An established connection was aborted by the software in your host machine]. Retry 1/3 in 1.50 seconds
2024-11-11 10:13:00,899 ERROR:Error sending data to server: Cannot connect to host your-server-url.com:443 ssl:<ssl.SSLContext object at 0x000001664F8545D0> [An established connection was aborted by the software in your host machine]. Retry 2/3 in 2.25 seconds
2024-11-11 10:13:03,634 ERROR:Error sending data to server: Cannot connect to host your-server-url.com:443 ssl:<ssl.SSLContext object at 0x000001664F8560D0> [An established connection was aborted by the software in your host machine]. Retry 3/3 in 3.38 seconds
2024-11-11 10:13:07,014 CRITICAL:Max retries reached. Failed to send data
2024-11-11 10:13:20,518 ERROR:Error sending data to SharePoint
Traceback (most recent call last):
  File "c:\Users\David.Peter\Downloads\Softwares & Drivers\Scripts\System monitoring\venv\Lib\site-packages\msal\authority.py", line 79, in __init__
    openid_config = tenant_discovery(
                    ^^^^^^^^^^^^^^^^^
  File "c:\Users\David.Peter\Downloads\Softwares & Drivers\Scripts\System monitoring\venv\Lib\site-packages\msal\authority.py", line 216, in tenant_discovery
    raise ValueError("OIDC Discovery failed on {}. HTTP status: {}, Error: {}".format(
ValueError: OIDC Discovery failed on https://login.microsoftonline.com/your_tenant_id/v2.0/.well-known/openid-configuration. HTTP status: 400, Error: {"error":"invalid_tenant","error_description":"AADSTS90002: Tenant 'your_tenant_id' not found. Check to make sure you have the correct tenant ID and are signing into the correct cloud. Check with your subscription administrator, this may happen if there are no active subscriptions for the tenant. Trace ID: 1a48c259-7217-45ae-9bfa-de25307c2c01 Correlation ID: 2b559f4e-7d01-4ec2-a2e4-5a361170f4e9 Timestamp: 2024-11-11 07:13:20Z","error_codes":[90002],"timestamp":"2024-11-11 07:13:20Z","trace_id":"1a48c259-7217-45ae-9bfa-de25307c2c01","correlation_id":"2b559f4e-7d01-4ec2-a2e4-5a361170f4e9","error_uri":"https://login.microsoftonline.com/error?code=90002"}

During handling of the above exception, another exception occurred:

Traceback (most recent call last):
  File "C:\Users\David.Peter\Downloads\Softwares & Drivers\Scripts\System monitoring\agent.py", line 281, in send_data_to_sharepoint
    app = ConfidentialClientApplication(
          ^^^^^^^^^^^^^^^^^^^^^^^^^^^^^^
  File "c:\Users\David.Peter\Downloads\Softwares & Drivers\Scripts\System monitoring\venv\Lib\site-packages\msal\application.py", line 608, in __init__
    self.authority = Authority(
                     ^^^^^^^^^^
  File "c:\Users\David.Peter\Downloads\Softwares & Drivers\Scripts\System monitoring\venv\Lib\site-packages\msal\authority.py", line 95, in __init__
    raise ValueError(error_message)
ValueError: Unable to get authority configuration for https://login.microsoftonline.com/your_tenant_id. Authority would typically be in a format of https://login.microsoftonline.com/your_tenant or https://tenant_name.ciamlogin.com or https://tenant_name.b2clogin.com/tenant.onmicrosoft.com/policy.  Also please double check your tenant name or GUID is correct.
2024-11-11 10:13:20,804 ERROR:Error sending data to server: Cannot connect to host your-server-url.com:443 ssl:<ssl.SSLContext object at 0x000001664F761850> [An established connection was aborted by the software in your host machine]. Retry 1/3 in 1.50 seconds
2024-11-11 10:13:22,699 ERROR:Error sending data to server: Cannot connect to host your-server-url.com:443 ssl:<ssl.SSLContext object at 0x000001664F827BD0> [An established connection was aborted by the software in your host machine]. Retry 2/3 in 2.25 seconds
2024-11-11 10:13:25,289 ERROR:Error sending data to server: Cannot connect to host your-server-url.com:443 ssl:<ssl.SSLContext object at 0x000001664F855DD0> [An established connection was aborted by the software in your host machine]. Retry 3/3 in 3.38 seconds
2024-11-11 10:13:28,668 CRITICAL:Max retries reached. Failed to send data
2024-11-11 10:13:42,342 ERROR:Error sending data to SharePoint
Traceback (most recent call last):
  File "c:\Users\David.Peter\Downloads\Softwares & Drivers\Scripts\System monitoring\venv\Lib\site-packages\msal\authority.py", line 79, in __init__
    openid_config = tenant_discovery(
                    ^^^^^^^^^^^^^^^^^
  File "c:\Users\David.Peter\Downloads\Softwares & Drivers\Scripts\System monitoring\venv\Lib\site-packages\msal\authority.py", line 216, in tenant_discovery
    raise ValueError("OIDC Discovery failed on {}. HTTP status: {}, Error: {}".format(
ValueError: OIDC Discovery failed on https://login.microsoftonline.com/your_tenant_id/v2.0/.well-known/openid-configuration. HTTP status: 400, Error: {"error":"invalid_tenant","error_description":"AADSTS90002: Tenant 'your_tenant_id' not found. Check to make sure you have the correct tenant ID and are signing into the correct cloud. Check with your subscription administrator, this may happen if there are no active subscriptions for the tenant. Trace ID: 9b1d7e81-ccf2-49c9-8c87-eee70d080f01 Correlation ID: 2fdc3aec-1488-4210-9cf8-32f03365d844 Timestamp: 2024-11-11 07:13:42Z","error_codes":[90002],"timestamp":"2024-11-11 07:13:42Z","trace_id":"9b1d7e81-ccf2-49c9-8c87-eee70d080f01","correlation_id":"2fdc3aec-1488-4210-9cf8-32f03365d844","error_uri":"https://login.microsoftonline.com/error?code=90002"}

During handling of the above exception, another exception occurred:

Traceback (most recent call last):
  File "C:\Users\David.Peter\Downloads\Softwares & Drivers\Scripts\System monitoring\agent.py", line 281, in send_data_to_sharepoint
    app = ConfidentialClientApplication(
          ^^^^^^^^^^^^^^^^^^^^^^^^^^^^^^
  File "c:\Users\David.Peter\Downloads\Softwares & Drivers\Scripts\System monitoring\venv\Lib\site-packages\msal\application.py", line 608, in __init__
    self.authority = Authority(
                     ^^^^^^^^^^
  File "c:\Users\David.Peter\Downloads\Softwares & Drivers\Scripts\System monitoring\venv\Lib\site-packages\msal\authority.py", line 95, in __init__
    raise ValueError(error_message)
ValueError: Unable to get authority configuration for https://login.microsoftonline.com/your_tenant_id. Authority would typically be in a format of https://login.microsoftonline.com/your_tenant or https://tenant_name.ciamlogin.com or https://tenant_name.b2clogin.com/tenant.onmicrosoft.com/policy.  Also please double check your tenant name or GUID is correct.
2024-11-11 10:13:42,753 ERROR:Error sending data to server: Cannot connect to host your-server-url.com:443 ssl:<ssl.SSLContext object at 0x000001664F854450> [An established connection was aborted by the software in your host machine]. Retry 1/3 in 1.50 seconds
2024-11-11 10:13:44,617 ERROR:Error sending data to server: Cannot connect to host your-server-url.com:443 ssl:<ssl.SSLContext object at 0x000001664F763450> [An established connection was aborted by the software in your host machine]. Retry 2/3 in 2.25 seconds
2024-11-11 10:13:47,463 ERROR:Error sending data to server: Cannot connect to host your-server-url.com:443 ssl:<ssl.SSLContext object at 0x000001664F826AD0> [An established connection was aborted by the software in your host machine]. Retry 3/3 in 3.38 seconds
2024-11-11 10:13:50,843 CRITICAL:Max retries reached. Failed to send data
2024-11-11 10:14:05,279 ERROR:Error sending data to SharePoint
Traceback (most recent call last):
  File "c:\Users\David.Peter\Downloads\Softwares & Drivers\Scripts\System monitoring\venv\Lib\site-packages\msal\authority.py", line 79, in __init__
    openid_config = tenant_discovery(
                    ^^^^^^^^^^^^^^^^^
  File "c:\Users\David.Peter\Downloads\Softwares & Drivers\Scripts\System monitoring\venv\Lib\site-packages\msal\authority.py", line 216, in tenant_discovery
    raise ValueError("OIDC Discovery failed on {}. HTTP status: {}, Error: {}".format(
ValueError: OIDC Discovery failed on https://login.microsoftonline.com/your_tenant_id/v2.0/.well-known/openid-configuration. HTTP status: 400, Error: {"error":"invalid_tenant","error_description":"AADSTS90002: Tenant 'your_tenant_id' not found. Check to make sure you have the correct tenant ID and are signing into the correct cloud. Check with your subscription administrator, this may happen if there are no active subscriptions for the tenant. Trace ID: a416dd68-a4c9-4ca8-a996-bea981311b00 Correlation ID: ad3dcb76-4493-4ea7-81dd-7be88ac8b267 Timestamp: 2024-11-11 07:14:05Z","error_codes":[90002],"timestamp":"2024-11-11 07:14:05Z","trace_id":"a416dd68-a4c9-4ca8-a996-bea981311b00","correlation_id":"ad3dcb76-4493-4ea7-81dd-7be88ac8b267","error_uri":"https://login.microsoftonline.com/error?code=90002"}

During handling of the above exception, another exception occurred:

Traceback (most recent call last):
  File "C:\Users\David.Peter\Downloads\Softwares & Drivers\Scripts\System monitoring\agent.py", line 281, in send_data_to_sharepoint
    app = ConfidentialClientApplication(
          ^^^^^^^^^^^^^^^^^^^^^^^^^^^^^^
  File "c:\Users\David.Peter\Downloads\Softwares & Drivers\Scripts\System monitoring\venv\Lib\site-packages\msal\application.py", line 608, in __init__
    self.authority = Authority(
                     ^^^^^^^^^^
  File "c:\Users\David.Peter\Downloads\Softwares & Drivers\Scripts\System monitoring\venv\Lib\site-packages\msal\authority.py", line 95, in __init__
    raise ValueError(error_message)
ValueError: Unable to get authority configuration for https://login.microsoftonline.com/your_tenant_id. Authority would typically be in a format of https://login.microsoftonline.com/your_tenant or https://tenant_name.ciamlogin.com or https://tenant_name.b2clogin.com/tenant.onmicrosoft.com/policy.  Also please double check your tenant name or GUID is correct.
2024-11-11 10:14:05,551 ERROR:Error sending data to server: Cannot connect to host your-server-url.com:443 ssl:<ssl.SSLContext object at 0x000001664F856350> [An established connection was aborted by the software in your host machine]. Retry 1/3 in 1.50 seconds
2024-11-11 10:14:07,532 ERROR:Error sending data to server: Cannot connect to host your-server-url.com:443 ssl:<ssl.SSLContext object at 0x000001664F854850> [An established connection was aborted by the software in your host machine]. Retry 2/3 in 2.25 seconds
2024-11-11 10:14:10,200 ERROR:Error sending data to server: Cannot connect to host your-server-url.com:443 ssl:<ssl.SSLContext object at 0x000001664F856750> [An established connection was aborted by the software in your host machine]. Retry 3/3 in 3.38 seconds
2024-11-11 10:14:13,588 CRITICAL:Max retries reached. Failed to send data
2024-11-11 10:14:27,197 ERROR:Error sending data to SharePoint
Traceback (most recent call last):
  File "c:\Users\David.Peter\Downloads\Softwares & Drivers\Scripts\System monitoring\venv\Lib\site-packages\msal\authority.py", line 79, in __init__
    openid_config = tenant_discovery(
                    ^^^^^^^^^^^^^^^^^
  File "c:\Users\David.Peter\Downloads\Softwares & Drivers\Scripts\System monitoring\venv\Lib\site-packages\msal\authority.py", line 216, in tenant_discovery
    raise ValueError("OIDC Discovery failed on {}. HTTP status: {}, Error: {}".format(
ValueError: OIDC Discovery failed on https://login.microsoftonline.com/your_tenant_id/v2.0/.well-known/openid-configuration. HTTP status: 400, Error: {"error":"invalid_tenant","error_description":"AADSTS90002: Tenant 'your_tenant_id' not found. Check to make sure you have the correct tenant ID and are signing into the correct cloud. Check with your subscription administrator, this may happen if there are no active subscriptions for the tenant. Trace ID: 33fe1812-51ec-49c8-ad0f-cdab5b16a200 Correlation ID: 95f5726d-4b1a-4e60-9f85-4073ea047702 Timestamp: 2024-11-11 07:14:27Z","error_codes":[90002],"timestamp":"2024-11-11 07:14:27Z","trace_id":"33fe1812-51ec-49c8-ad0f-cdab5b16a200","correlation_id":"95f5726d-4b1a-4e60-9f85-4073ea047702","error_uri":"https://login.microsoftonline.com/error?code=90002"}

During handling of the above exception, another exception occurred:

Traceback (most recent call last):
  File "C:\Users\David.Peter\Downloads\Softwares & Drivers\Scripts\System monitoring\agent.py", line 281, in send_data_to_sharepoint
    app = ConfidentialClientApplication(
          ^^^^^^^^^^^^^^^^^^^^^^^^^^^^^^
  File "c:\Users\David.Peter\Downloads\Softwares & Drivers\Scripts\System monitoring\venv\Lib\site-packages\msal\application.py", line 608, in __init__
    self.authority = Authority(
                     ^^^^^^^^^^
  File "c:\Users\David.Peter\Downloads\Softwares & Drivers\Scripts\System monitoring\venv\Lib\site-packages\msal\authority.py", line 95, in __init__
    raise ValueError(error_message)
ValueError: Unable to get authority configuration for https://login.microsoftonline.com/your_tenant_id. Authority would typically be in a format of https://login.microsoftonline.com/your_tenant or https://tenant_name.ciamlogin.com or https://tenant_name.b2clogin.com/tenant.onmicrosoft.com/policy.  Also please double check your tenant name or GUID is correct.
2024-11-11 10:14:27,475 ERROR:Error sending data to server: Cannot connect to host your-server-url.com:443 ssl:<ssl.SSLContext object at 0x000001664F763D50> [An established connection was aborted by the software in your host machine]. Retry 1/3 in 1.50 seconds
2024-11-11 10:14:29,358 ERROR:Error sending data to server: Cannot connect to host your-server-url.com:443 ssl:<ssl.SSLContext object at 0x000001664F5A7750> [An established connection was aborted by the software in your host machine]. Retry 2/3 in 2.25 seconds
2024-11-11 10:14:31,971 ERROR:Error sending data to server: Cannot connect to host your-server-url.com:443 ssl:<ssl.SSLContext object at 0x000001664F8541D0> [An established connection was aborted by the software in your host machine]. Retry 3/3 in 3.38 seconds
2024-11-11 10:14:35,369 CRITICAL:Max retries reached. Failed to send data
2024-11-11 10:14:50,337 INFO:Received signal to terminate. Shutting down gracefully...
2024-11-11 10:14:50,539 ERROR:Error sending data to SharePoint
Traceback (most recent call last):
  File "c:\Users\David.Peter\Downloads\Softwares & Drivers\Scripts\System monitoring\venv\Lib\site-packages\msal\authority.py", line 79, in __init__
    openid_config = tenant_discovery(
                    ^^^^^^^^^^^^^^^^^
  File "c:\Users\David.Peter\Downloads\Softwares & Drivers\Scripts\System monitoring\venv\Lib\site-packages\msal\authority.py", line 216, in tenant_discovery
    raise ValueError("OIDC Discovery failed on {}. HTTP status: {}, Error: {}".format(
ValueError: OIDC Discovery failed on https://login.microsoftonline.com/your_tenant_id/v2.0/.well-known/openid-configuration. HTTP status: 400, Error: {"error":"invalid_tenant","error_description":"AADSTS90002: Tenant 'your_tenant_id' not found. Check to make sure you have the correct tenant ID and are signing into the correct cloud. Check with your subscription administrator, this may happen if there are no active subscriptions for the tenant. Trace ID: 3d6584ef-4844-444d-872c-0b4e87e7b000 Correlation ID: 03092815-904e-4c95-90ef-b971feb461ae Timestamp: 2024-11-11 07:14:50Z","error_codes":[90002],"timestamp":"2024-11-11 07:14:50Z","trace_id":"3d6584ef-4844-444d-872c-0b4e87e7b000","correlation_id":"03092815-904e-4c95-90ef-b971feb461ae","error_uri":"https://login.microsoftonline.com/error?code=90002"}

During handling of the above exception, another exception occurred:

Traceback (most recent call last):
  File "C:\Users\David.Peter\Downloads\Softwares & Drivers\Scripts\System monitoring\agent.py", line 281, in send_data_to_sharepoint
    app = ConfidentialClientApplication(
          ^^^^^^^^^^^^^^^^^^^^^^^^^^^^^^
  File "c:\Users\David.Peter\Downloads\Softwares & Drivers\Scripts\System monitoring\venv\Lib\site-packages\msal\application.py", line 608, in __init__
    self.authority = Authority(
                     ^^^^^^^^^^
  File "c:\Users\David.Peter\Downloads\Softwares & Drivers\Scripts\System monitoring\venv\Lib\site-packages\msal\authority.py", line 95, in __init__
    raise ValueError(error_message)
ValueError: Unable to get authority configuration for https://login.microsoftonline.com/your_tenant_id. Authority would typically be in a format of https://login.microsoftonline.com/your_tenant or https://tenant_name.ciamlogin.com or https://tenant_name.b2clogin.com/tenant.onmicrosoft.com/policy.  Also please double check your tenant name or GUID is correct.
2024-11-11 10:14:50,543 ERROR:An error occurred while running the main loop
Traceback (most recent call last):
  File "C:\Users\David.Peter\Downloads\Softwares & Drivers\Scripts\System monitoring\agent.py", line 394, in <module>
    asyncio.run(main_loop())
  File "C:\Users\David.Peter\AppData\Local\Programs\Python\Python312\Lib\asyncio\runners.py", line 194, in run
    return runner.run(main)
           ^^^^^^^^^^^^^^^^
  File "C:\Users\David.Peter\AppData\Local\Programs\Python\Python312\Lib\asyncio\runners.py", line 118, in run
    return self._loop.run_until_complete(task)
           ^^^^^^^^^^^^^^^^^^^^^^^^^^^^^^^^^^^
  File "C:\Users\David.Peter\AppData\Local\Programs\Python\Python312\Lib\asyncio\base_events.py", line 685, in run_until_complete
    raise RuntimeError('Event loop stopped before Future completed.')
RuntimeError: Event loop stopped before Future completed.
2024-11-11 10:14:50,555 INFO:Clinic server monitor shut down
