2024-11-11 12:51:43,622 WARNING:Running in DEBUG MODE. Sensitive information may be logged.
2024-11-11 12:51:51,379 ERROR:Error sending data to SharePoint
Traceback (most recent call last):
  File "C:\Users\David.Peter\AppData\Local\Programs\Python\Python312\Lib\site-packages\msal\authority.py", line 79, in __init__
    openid_config = tenant_discovery(
                    ^^^^^^^^^^^^^^^^^
  File "C:\Users\David.Peter\AppData\Local\Programs\Python\Python312\Lib\site-packages\msal\authority.py", line 216, in tenant_discovery
    raise ValueError("OIDC Discovery failed on {}. HTTP status: {}, Error: {}".format(
ValueError: OIDC Discovery failed on https://login.microsoftonline.com/your_tenant_id/v2.0/.well-known/openid-configuration. HTTP status: 400, Error: {"error":"invalid_tenant","error_description":"AADSTS90002: Tenant 'your_tenant_id' not found. Check to make sure you have the correct tenant ID and are signing into the correct cloud. Check with your subscription administrator, this may happen if there are no active subscriptions for the tenant. Trace ID: 1f54dbc3-9d80-4843-8168-bd635d64f700 Correlation ID: 38647092-f6b4-42ec-91ee-453bb43b9371 Timestamp: 2024-11-11 09:51:51Z","error_codes":[90002],"timestamp":"2024-11-11 09:51:51Z","trace_id":"1f54dbc3-9d80-4843-8168-bd635d64f700","correlation_id":"38647092-f6b4-42ec-91ee-453bb43b9371","error_uri":"https://login.microsoftonline.com/error?code=90002"}

During handling of the above exception, another exception occurred:

Traceback (most recent call last):
  File "C:\Users\David.Peter\Downloads\Softwares & Drivers\Scripts\System monitoring\agent.py", line 281, in send_data_to_sharepoint
    app = ConfidentialClientApplication(
          ^^^^^^^^^^^^^^^^^^^^^^^^^^^^^^
  File "C:\Users\David.Peter\AppData\Local\Programs\Python\Python312\Lib\site-packages\msal\application.py", line 608, in __init__
    self.authority = Authority(
                     ^^^^^^^^^^
  File "C:\Users\David.Peter\AppData\Local\Programs\Python\Python312\Lib\site-packages\msal\authority.py", line 95, in __init__
    raise ValueError(error_message)
ValueError: Unable to get authority configuration for https://login.microsoftonline.com/your_tenant_id. Authority would typically be in a format of https://login.microsoftonline.com/your_tenant or https://tenant_name.ciamlogin.com or https://tenant_name.b2clogin.com/tenant.onmicrosoft.com/policy.  Also please double check your tenant name or GUID is correct.
2024-11-11 12:51:52,967 ERROR:Error sending data to server: [Errno None] Can not write request body for https://your-server-url.com/api. Retry 1/3 in 1.50 seconds
2024-11-11 12:51:54,920 ERROR:Error sending data to server: Cannot connect to host your-server-url.com:443 ssl:<ssl.SSLContext object at 0x000001FE7B909BD0> [An established connection was aborted by the software in your host machine]. Retry 2/3 in 2.25 seconds
2024-11-11 12:51:58,169 ERROR:Error sending data to server: Cannot connect to host your-server-url.com:443 ssl:<ssl.SSLContext object at 0x000001FE7BB37050> [An established connection was aborted by the software in your host machine]. Retry 3/3 in 3.38 seconds
2024-11-11 12:52:01,551 CRITICAL:Max retries reached. Failed to send data
2024-11-11 12:52:15,205 ERROR:Error sending data to SharePoint
Traceback (most recent call last):
  File "C:\Users\David.Peter\AppData\Local\Programs\Python\Python312\Lib\site-packages\msal\authority.py", line 79, in __init__
    openid_config = tenant_discovery(
                    ^^^^^^^^^^^^^^^^^
  File "C:\Users\David.Peter\AppData\Local\Programs\Python\Python312\Lib\site-packages\msal\authority.py", line 216, in tenant_discovery
    raise ValueError("OIDC Discovery failed on {}. HTTP status: {}, Error: {}".format(
ValueError: OIDC Discovery failed on https://login.microsoftonline.com/your_tenant_id/v2.0/.well-known/openid-configuration. HTTP status: 400, Error: {"error":"invalid_tenant","error_description":"AADSTS90002: Tenant 'your_tenant_id' not found. Check to make sure you have the correct tenant ID and are signing into the correct cloud. Check with your subscription administrator, this may happen if there are no active subscriptions for the tenant. Trace ID: a004d57e-41e1-4621-8203-24691ec89100 Correlation ID: 47112f9e-1111-45e1-bbd2-4a088df478f8 Timestamp: 2024-11-11 09:52:15Z","error_codes":[90002],"timestamp":"2024-11-11 09:52:15Z","trace_id":"a004d57e-41e1-4621-8203-24691ec89100","correlation_id":"47112f9e-1111-45e1-bbd2-4a088df478f8","error_uri":"https://login.microsoftonline.com/error?code=90002"}

During handling of the above exception, another exception occurred:

Traceback (most recent call last):
  File "C:\Users\David.Peter\Downloads\Softwares & Drivers\Scripts\System monitoring\agent.py", line 281, in send_data_to_sharepoint
    app = ConfidentialClientApplication(
          ^^^^^^^^^^^^^^^^^^^^^^^^^^^^^^
  File "C:\Users\David.Peter\AppData\Local\Programs\Python\Python312\Lib\site-packages\msal\application.py", line 608, in __init__
    self.authority = Authority(
                     ^^^^^^^^^^
  File "C:\Users\David.Peter\AppData\Local\Programs\Python\Python312\Lib\site-packages\msal\authority.py", line 95, in __init__
    raise ValueError(error_message)
ValueError: Unable to get authority configuration for https://login.microsoftonline.com/your_tenant_id. Authority would typically be in a format of https://login.microsoftonline.com/your_tenant or https://tenant_name.ciamlogin.com or https://tenant_name.b2clogin.com/tenant.onmicrosoft.com/policy.  Also please double check your tenant name or GUID is correct.
2024-11-11 12:52:15,545 ERROR:Error sending data to server: Cannot connect to host your-server-url.com:443 ssl:<ssl.SSLContext object at 0x000001FE7BB37150> [An established connection was aborted by the software in your host machine]. Retry 1/3 in 1.50 seconds
2024-11-11 12:52:17,457 ERROR:Error sending data to server: Cannot connect to host your-server-url.com:443 ssl:<ssl.SSLContext object at 0x000001FE7BB37AD0> [An established connection was aborted by the software in your host machine]. Retry 2/3 in 2.25 seconds
2024-11-11 12:52:20,365 ERROR:Error sending data to server: Cannot connect to host your-server-url.com:443 ssl:<ssl.SSLContext object at 0x000001FE7BB506D0> [An established connection was aborted by the software in your host machine]. Retry 3/3 in 3.38 seconds
2024-11-11 12:52:23,741 CRITICAL:Max retries reached. Failed to send data
2024-11-11 12:52:37,995 ERROR:Error sending data to SharePoint
Traceback (most recent call last):
  File "C:\Users\David.Peter\AppData\Local\Programs\Python\Python312\Lib\site-packages\msal\authority.py", line 79, in __init__
    openid_config = tenant_discovery(
                    ^^^^^^^^^^^^^^^^^
  File "C:\Users\David.Peter\AppData\Local\Programs\Python\Python312\Lib\site-packages\msal\authority.py", line 216, in tenant_discovery
    raise ValueError("OIDC Discovery failed on {}. HTTP status: {}, Error: {}".format(
ValueError: OIDC Discovery failed on https://login.microsoftonline.com/your_tenant_id/v2.0/.well-known/openid-configuration. HTTP status: 400, Error: {"error":"invalid_tenant","error_description":"AADSTS90002: Tenant 'your_tenant_id' not found. Check to make sure you have the correct tenant ID and are signing into the correct cloud. Check with your subscription administrator, this may happen if there are no active subscriptions for the tenant. Trace ID: 36a29281-560a-4818-bc74-89028eebd300 Correlation ID: 014ad9a0-cfa8-47b6-8339-13ba3e8fff69 Timestamp: 2024-11-11 09:52:37Z","error_codes":[90002],"timestamp":"2024-11-11 09:52:37Z","trace_id":"36a29281-560a-4818-bc74-89028eebd300","correlation_id":"014ad9a0-cfa8-47b6-8339-13ba3e8fff69","error_uri":"https://login.microsoftonline.com/error?code=90002"}

During handling of the above exception, another exception occurred:

Traceback (most recent call last):
  File "C:\Users\David.Peter\Downloads\Softwares & Drivers\Scripts\System monitoring\agent.py", line 281, in send_data_to_sharepoint
    app = ConfidentialClientApplication(
          ^^^^^^^^^^^^^^^^^^^^^^^^^^^^^^
  File "C:\Users\David.Peter\AppData\Local\Programs\Python\Python312\Lib\site-packages\msal\application.py", line 608, in __init__
    self.authority = Authority(
                     ^^^^^^^^^^
  File "C:\Users\David.Peter\AppData\Local\Programs\Python\Python312\Lib\site-packages\msal\authority.py", line 95, in __init__
    raise ValueError(error_message)
ValueError: Unable to get authority configuration for https://login.microsoftonline.com/your_tenant_id. Authority would typically be in a format of https://login.microsoftonline.com/your_tenant or https://tenant_name.ciamlogin.com or https://tenant_name.b2clogin.com/tenant.onmicrosoft.com/policy.  Also please double check your tenant name or GUID is correct.
2024-11-11 12:52:38,332 ERROR:Error sending data to server: Cannot connect to host your-server-url.com:443 ssl:<ssl.SSLContext object at 0x000001FE7BB508D0> [An established connection was aborted by the software in your host machine]. Retry 1/3 in 1.50 seconds
2024-11-11 12:52:40,248 ERROR:Error sending data to server: Cannot connect to host your-server-url.com:443 ssl:<ssl.SSLContext object at 0x000001FE7BB51F50> [An established connection was aborted by the software in your host machine]. Retry 2/3 in 2.25 seconds
2024-11-11 12:52:43,014 ERROR:Error sending data to server: Cannot connect to host your-server-url.com:443 ssl:<ssl.SSLContext object at 0x000001FE7BB521D0> [An established connection was aborted by the software in your host machine]. Retry 3/3 in 3.38 seconds
2024-11-11 12:52:46,391 CRITICAL:Max retries reached. Failed to send data
2024-11-11 12:53:00,690 ERROR:Error sending data to SharePoint
Traceback (most recent call last):
  File "C:\Users\David.Peter\AppData\Local\Programs\Python\Python312\Lib\site-packages\msal\authority.py", line 79, in __init__
    openid_config = tenant_discovery(
                    ^^^^^^^^^^^^^^^^^
  File "C:\Users\David.Peter\AppData\Local\Programs\Python\Python312\Lib\site-packages\msal\authority.py", line 216, in tenant_discovery
    raise ValueError("OIDC Discovery failed on {}. HTTP status: {}, Error: {}".format(
ValueError: OIDC Discovery failed on https://login.microsoftonline.com/your_tenant_id/v2.0/.well-known/openid-configuration. HTTP status: 400, Error: {"error":"invalid_tenant","error_description":"AADSTS90002: Tenant 'your_tenant_id' not found. Check to make sure you have the correct tenant ID and are signing into the correct cloud. Check with your subscription administrator, this may happen if there are no active subscriptions for the tenant. Trace ID: f8cd7bf8-b5b0-4bce-bb9f-3e1014f14e03 Correlation ID: cf7046ab-8bb7-4601-a62b-6dde94c215ac Timestamp: 2024-11-11 09:53:00Z","error_codes":[90002],"timestamp":"2024-11-11 09:53:00Z","trace_id":"f8cd7bf8-b5b0-4bce-bb9f-3e1014f14e03","correlation_id":"cf7046ab-8bb7-4601-a62b-6dde94c215ac","error_uri":"https://login.microsoftonline.com/error?code=90002"}

During handling of the above exception, another exception occurred:

Traceback (most recent call last):
  File "C:\Users\David.Peter\Downloads\Softwares & Drivers\Scripts\System monitoring\agent.py", line 281, in send_data_to_sharepoint
    app = ConfidentialClientApplication(
          ^^^^^^^^^^^^^^^^^^^^^^^^^^^^^^
  File "C:\Users\David.Peter\AppData\Local\Programs\Python\Python312\Lib\site-packages\msal\application.py", line 608, in __init__
    self.authority = Authority(
                     ^^^^^^^^^^
  File "C:\Users\David.Peter\AppData\Local\Programs\Python\Python312\Lib\site-packages\msal\authority.py", line 95, in __init__
    raise ValueError(error_message)
ValueError: Unable to get authority configuration for https://login.microsoftonline.com/your_tenant_id. Authority would typically be in a format of https://login.microsoftonline.com/your_tenant or https://tenant_name.ciamlogin.com or https://tenant_name.b2clogin.com/tenant.onmicrosoft.com/policy.  Also please double check your tenant name or GUID is correct.
2024-11-11 12:53:01,112 ERROR:Error sending data to server: Cannot connect to host your-server-url.com:443 ssl:<ssl.SSLContext object at 0x000001FE7B9085D0> [An established connection was aborted by the software in your host machine]. Retry 1/3 in 1.50 seconds
2024-11-11 12:53:03,082 ERROR:Error sending data to server: Cannot connect to host your-server-url.com:443 ssl:<ssl.SSLContext object at 0x000001FE7B909D50> [An established connection was aborted by the software in your host machine]. Retry 2/3 in 2.25 seconds
2024-11-11 12:53:05,767 ERROR:Error sending data to server: Cannot connect to host your-server-url.com:443 ssl:<ssl.SSLContext object at 0x000001FE7BB513D0> [An established connection was aborted by the software in your host machine]. Retry 3/3 in 3.38 seconds
2024-11-11 12:53:09,156 CRITICAL:Max retries reached. Failed to send data
2024-11-11 12:53:23,704 ERROR:Error sending data to SharePoint
Traceback (most recent call last):
  File "C:\Users\David.Peter\AppData\Local\Programs\Python\Python312\Lib\site-packages\msal\authority.py", line 79, in __init__
    openid_config = tenant_discovery(
                    ^^^^^^^^^^^^^^^^^
  File "C:\Users\David.Peter\AppData\Local\Programs\Python\Python312\Lib\site-packages\msal\authority.py", line 216, in tenant_discovery
    raise ValueError("OIDC Discovery failed on {}. HTTP status: {}, Error: {}".format(
ValueError: OIDC Discovery failed on https://login.microsoftonline.com/your_tenant_id/v2.0/.well-known/openid-configuration. HTTP status: 400, Error: {"error":"invalid_tenant","error_description":"AADSTS90002: Tenant 'your_tenant_id' not found. Check to make sure you have the correct tenant ID and are signing into the correct cloud. Check with your subscription administrator, this may happen if there are no active subscriptions for the tenant. Trace ID: a5ca0ff4-7961-49ce-81a4-536494ec2500 Correlation ID: 1f34d139-07fd-4fcf-992f-d5ad6b2e7d6f Timestamp: 2024-11-11 09:53:23Z","error_codes":[90002],"timestamp":"2024-11-11 09:53:23Z","trace_id":"a5ca0ff4-7961-49ce-81a4-536494ec2500","correlation_id":"1f34d139-07fd-4fcf-992f-d5ad6b2e7d6f","error_uri":"https://login.microsoftonline.com/error?code=90002"}

During handling of the above exception, another exception occurred:

Traceback (most recent call last):
  File "C:\Users\David.Peter\Downloads\Softwares & Drivers\Scripts\System monitoring\agent.py", line 281, in send_data_to_sharepoint
    app = ConfidentialClientApplication(
          ^^^^^^^^^^^^^^^^^^^^^^^^^^^^^^
  File "C:\Users\David.Peter\AppData\Local\Programs\Python\Python312\Lib\site-packages\msal\application.py", line 608, in __init__
    self.authority = Authority(
                     ^^^^^^^^^^
  File "C:\Users\David.Peter\AppData\Local\Programs\Python\Python312\Lib\site-packages\msal\authority.py", line 95, in __init__
    raise ValueError(error_message)
ValueError: Unable to get authority configuration for https://login.microsoftonline.com/your_tenant_id. Authority would typically be in a format of https://login.microsoftonline.com/your_tenant or https://tenant_name.ciamlogin.com or https://tenant_name.b2clogin.com/tenant.onmicrosoft.com/policy.  Also please double check your tenant name or GUID is correct.
2024-11-11 12:53:24,073 ERROR:Error sending data to server: Cannot connect to host your-server-url.com:443 ssl:<ssl.SSLContext object at 0x000001FE7BB51D50> [An established connection was aborted by the software in your host machine]. Retry 1/3 in 1.50 seconds
2024-11-11 12:53:26,189 ERROR:Error sending data to server: Cannot connect to host your-server-url.com:443 ssl:<ssl.SSLContext object at 0x000001FE7BB37CD0> [An established connection was aborted by the software in your host machine]. Retry 2/3 in 2.25 seconds
2024-11-11 12:53:28,887 ERROR:Error sending data to server: Cannot connect to host your-server-url.com:443 ssl:<ssl.SSLContext object at 0x000001FE7BB37E50> [An established connection was aborted by the software in your host machine]. Retry 3/3 in 3.38 seconds
2024-11-11 12:53:32,276 CRITICAL:Max retries reached. Failed to send data
2024-11-11 12:53:45,873 ERROR:Error sending data to SharePoint
Traceback (most recent call last):
  File "C:\Users\David.Peter\AppData\Local\Programs\Python\Python312\Lib\site-packages\msal\authority.py", line 79, in __init__
    openid_config = tenant_discovery(
                    ^^^^^^^^^^^^^^^^^
  File "C:\Users\David.Peter\AppData\Local\Programs\Python\Python312\Lib\site-packages\msal\authority.py", line 216, in tenant_discovery
    raise ValueError("OIDC Discovery failed on {}. HTTP status: {}, Error: {}".format(
ValueError: OIDC Discovery failed on https://login.microsoftonline.com/your_tenant_id/v2.0/.well-known/openid-configuration. HTTP status: 400, Error: {"error":"invalid_tenant","error_description":"AADSTS90002: Tenant 'your_tenant_id' not found. Check to make sure you have the correct tenant ID and are signing into the correct cloud. Check with your subscription administrator, this may happen if there are no active subscriptions for the tenant. Trace ID: 135951cd-0b0a-404f-b557-3f47d297f400 Correlation ID: 49fb1c20-8e96-4d36-85d2-4445edef05aa Timestamp: 2024-11-11 09:53:45Z","error_codes":[90002],"timestamp":"2024-11-11 09:53:45Z","trace_id":"135951cd-0b0a-404f-b557-3f47d297f400","correlation_id":"49fb1c20-8e96-4d36-85d2-4445edef05aa","error_uri":"https://login.microsoftonline.com/error?code=90002"}

During handling of the above exception, another exception occurred:

Traceback (most recent call last):
  File "C:\Users\David.Peter\Downloads\Softwares & Drivers\Scripts\System monitoring\agent.py", line 281, in send_data_to_sharepoint
    app = ConfidentialClientApplication(
          ^^^^^^^^^^^^^^^^^^^^^^^^^^^^^^
  File "C:\Users\David.Peter\AppData\Local\Programs\Python\Python312\Lib\site-packages\msal\application.py", line 608, in __init__
    self.authority = Authority(
                     ^^^^^^^^^^
  File "C:\Users\David.Peter\AppData\Local\Programs\Python\Python312\Lib\site-packages\msal\authority.py", line 95, in __init__
    raise ValueError(error_message)
ValueError: Unable to get authority configuration for https://login.microsoftonline.com/your_tenant_id. Authority would typically be in a format of https://login.microsoftonline.com/your_tenant or https://tenant_name.ciamlogin.com or https://tenant_name.b2clogin.com/tenant.onmicrosoft.com/policy.  Also please double check your tenant name or GUID is correct.
2024-11-11 12:53:46,276 ERROR:Error sending data to server: Cannot connect to host your-server-url.com:443 ssl:<ssl.SSLContext object at 0x000001FE7BB506D0> [An established connection was aborted by the software in your host machine]. Retry 1/3 in 1.50 seconds
2024-11-11 12:53:48,231 ERROR:Error sending data to server: Cannot connect to host your-server-url.com:443 ssl:<ssl.SSLContext object at 0x000001FE7BB52FD0> [An established connection was aborted by the software in your host machine]. Retry 2/3 in 2.25 seconds
2024-11-11 12:53:50,927 ERROR:Error sending data to server: Cannot connect to host your-server-url.com:443 ssl:<ssl.SSLContext object at 0x000001FE7BB53750> [An established connection was aborted by the software in your host machine]. Retry 3/3 in 3.38 seconds
2024-11-11 12:53:54,305 CRITICAL:Max retries reached. Failed to send data
2024-11-11 12:54:08,909 ERROR:Error sending data to SharePoint
Traceback (most recent call last):
  File "C:\Users\David.Peter\AppData\Local\Programs\Python\Python312\Lib\site-packages\msal\authority.py", line 79, in __init__
    openid_config = tenant_discovery(
                    ^^^^^^^^^^^^^^^^^
  File "C:\Users\David.Peter\AppData\Local\Programs\Python\Python312\Lib\site-packages\msal\authority.py", line 216, in tenant_discovery
    raise ValueError("OIDC Discovery failed on {}. HTTP status: {}, Error: {}".format(
ValueError: OIDC Discovery failed on https://login.microsoftonline.com/your_tenant_id/v2.0/.well-known/openid-configuration. HTTP status: 400, Error: {"error":"invalid_tenant","error_description":"AADSTS90002: Tenant 'your_tenant_id' not found. Check to make sure you have the correct tenant ID and are signing into the correct cloud. Check with your subscription administrator, this may happen if there are no active subscriptions for the tenant. Trace ID: 169f8d06-ac8c-4007-ada5-eeb75c128b00 Correlation ID: fe1d8e0b-d8df-4563-9827-ba3466335a02 Timestamp: 2024-11-11 09:54:08Z","error_codes":[90002],"timestamp":"2024-11-11 09:54:08Z","trace_id":"169f8d06-ac8c-4007-ada5-eeb75c128b00","correlation_id":"fe1d8e0b-d8df-4563-9827-ba3466335a02","error_uri":"https://login.microsoftonline.com/error?code=90002"}

During handling of the above exception, another exception occurred:

Traceback (most recent call last):
  File "C:\Users\David.Peter\Downloads\Softwares & Drivers\Scripts\System monitoring\agent.py", line 281, in send_data_to_sharepoint
    app = ConfidentialClientApplication(
          ^^^^^^^^^^^^^^^^^^^^^^^^^^^^^^
  File "C:\Users\David.Peter\AppData\Local\Programs\Python\Python312\Lib\site-packages\msal\application.py", line 608, in __init__
    self.authority = Authority(
                     ^^^^^^^^^^
  File "C:\Users\David.Peter\AppData\Local\Programs\Python\Python312\Lib\site-packages\msal\authority.py", line 95, in __init__
    raise ValueError(error_message)
ValueError: Unable to get authority configuration for https://login.microsoftonline.com/your_tenant_id. Authority would typically be in a format of https://login.microsoftonline.com/your_tenant or https://tenant_name.ciamlogin.com or https://tenant_name.b2clogin.com/tenant.onmicrosoft.com/policy.  Also please double check your tenant name or GUID is correct.
2024-11-11 12:54:09,267 ERROR:Error sending data to server: Cannot connect to host your-server-url.com:443 ssl:<ssl.SSLContext object at 0x000001FE7BB37E50> [An established connection was aborted by the software in your host machine]. Retry 1/3 in 1.50 seconds
2024-11-11 12:54:11,283 ERROR:Error sending data to server: Cannot connect to host your-server-url.com:443 ssl:<ssl.SSLContext object at 0x000001FE7BB37DD0> [An established connection was aborted by the software in your host machine]. Retry 2/3 in 2.25 seconds
2024-11-11 12:54:14,053 ERROR:Error sending data to server: Cannot connect to host your-server-url.com:443 ssl:<ssl.SSLContext object at 0x000001FE7BB51ED0> [An established connection was aborted by the software in your host machine]. Retry 3/3 in 3.38 seconds
2024-11-11 12:54:17,431 CRITICAL:Max retries reached. Failed to send data
2024-11-11 12:54:31,631 ERROR:Error sending data to SharePoint
Traceback (most recent call last):
  File "C:\Users\David.Peter\AppData\Local\Programs\Python\Python312\Lib\site-packages\msal\authority.py", line 79, in __init__
    openid_config = tenant_discovery(
                    ^^^^^^^^^^^^^^^^^
  File "C:\Users\David.Peter\AppData\Local\Programs\Python\Python312\Lib\site-packages\msal\authority.py", line 216, in tenant_discovery
    raise ValueError("OIDC Discovery failed on {}. HTTP status: {}, Error: {}".format(
ValueError: OIDC Discovery failed on https://login.microsoftonline.com/your_tenant_id/v2.0/.well-known/openid-configuration. HTTP status: 400, Error: {"error":"invalid_tenant","error_description":"AADSTS90002: Tenant 'your_tenant_id' not found. Check to make sure you have the correct tenant ID and are signing into the correct cloud. Check with your subscription administrator, this may happen if there are no active subscriptions for the tenant. Trace ID: 54b59f4b-6253-47a1-a78b-d78a2c387100 Correlation ID: 2204075b-3ea1-4cb7-876a-3c6389e61715 Timestamp: 2024-11-11 09:54:31Z","error_codes":[90002],"timestamp":"2024-11-11 09:54:31Z","trace_id":"54b59f4b-6253-47a1-a78b-d78a2c387100","correlation_id":"2204075b-3ea1-4cb7-876a-3c6389e61715","error_uri":"https://login.microsoftonline.com/error?code=90002"}

During handling of the above exception, another exception occurred:

Traceback (most recent call last):
  File "C:\Users\David.Peter\Downloads\Softwares & Drivers\Scripts\System monitoring\agent.py", line 281, in send_data_to_sharepoint
    app = ConfidentialClientApplication(
          ^^^^^^^^^^^^^^^^^^^^^^^^^^^^^^
  File "C:\Users\David.Peter\AppData\Local\Programs\Python\Python312\Lib\site-packages\msal\application.py", line 608, in __init__
    self.authority = Authority(
                     ^^^^^^^^^^
  File "C:\Users\David.Peter\AppData\Local\Programs\Python\Python312\Lib\site-packages\msal\authority.py", line 95, in __init__
    raise ValueError(error_message)
ValueError: Unable to get authority configuration for https://login.microsoftonline.com/your_tenant_id. Authority would typically be in a format of https://login.microsoftonline.com/your_tenant or https://tenant_name.ciamlogin.com or https://tenant_name.b2clogin.com/tenant.onmicrosoft.com/policy.  Also please double check your tenant name or GUID is correct.
2024-11-11 12:54:32,011 ERROR:Error sending data to server: Cannot connect to host your-server-url.com:443 ssl:<ssl.SSLContext object at 0x000001FE7BB522D0> [An established connection was aborted by the software in your host machine]. Retry 1/3 in 1.50 seconds
2024-11-11 12:54:34,019 ERROR:Error sending data to server: Cannot connect to host your-server-url.com:443 ssl:<ssl.SSLContext object at 0x000001FE7B9098D0> [An established connection was aborted by the software in your host machine]. Retry 2/3 in 2.25 seconds
2024-11-11 12:54:36,784 ERROR:Error sending data to server: Cannot connect to host your-server-url.com:443 ssl:<ssl.SSLContext object at 0x000001FE7BAAA0D0> [An established connection was aborted by the software in your host machine]. Retry 3/3 in 3.38 seconds
2024-11-11 12:54:40,171 CRITICAL:Max retries reached. Failed to send data
2024-11-11 12:54:53,926 ERROR:Error sending data to SharePoint
Traceback (most recent call last):
  File "C:\Users\David.Peter\AppData\Local\Programs\Python\Python312\Lib\site-packages\msal\authority.py", line 79, in __init__
    openid_config = tenant_discovery(
                    ^^^^^^^^^^^^^^^^^
  File "C:\Users\David.Peter\AppData\Local\Programs\Python\Python312\Lib\site-packages\msal\authority.py", line 216, in tenant_discovery
    raise ValueError("OIDC Discovery failed on {}. HTTP status: {}, Error: {}".format(
ValueError: OIDC Discovery failed on https://login.microsoftonline.com/your_tenant_id/v2.0/.well-known/openid-configuration. HTTP status: 400, Error: {"error":"invalid_tenant","error_description":"AADSTS90002: Tenant 'your_tenant_id' not found. Check to make sure you have the correct tenant ID and are signing into the correct cloud. Check with your subscription administrator, this may happen if there are no active subscriptions for the tenant. Trace ID: 03a5bd68-9ee3-43f1-b40f-1d4192957a03 Correlation ID: 1d563108-8da5-440d-a94e-e58b779c1150 Timestamp: 2024-11-11 09:54:53Z","error_codes":[90002],"timestamp":"2024-11-11 09:54:53Z","trace_id":"03a5bd68-9ee3-43f1-b40f-1d4192957a03","correlation_id":"1d563108-8da5-440d-a94e-e58b779c1150","error_uri":"https://login.microsoftonline.com/error?code=90002"}

During handling of the above exception, another exception occurred:

Traceback (most recent call last):
  File "C:\Users\David.Peter\Downloads\Softwares & Drivers\Scripts\System monitoring\agent.py", line 281, in send_data_to_sharepoint
    app = ConfidentialClientApplication(
          ^^^^^^^^^^^^^^^^^^^^^^^^^^^^^^
  File "C:\Users\David.Peter\AppData\Local\Programs\Python\Python312\Lib\site-packages\msal\application.py", line 608, in __init__
    self.authority = Authority(
                     ^^^^^^^^^^
  File "C:\Users\David.Peter\AppData\Local\Programs\Python\Python312\Lib\site-packages\msal\authority.py", line 95, in __init__
    raise ValueError(error_message)
ValueError: Unable to get authority configuration for https://login.microsoftonline.com/your_tenant_id. Authority would typically be in a format of https://login.microsoftonline.com/your_tenant or https://tenant_name.ciamlogin.com or https://tenant_name.b2clogin.com/tenant.onmicrosoft.com/policy.  Also please double check your tenant name or GUID is correct.
2024-11-11 12:54:54,397 ERROR:Error sending data to server: Cannot connect to host your-server-url.com:443 ssl:<ssl.SSLContext object at 0x000001FE7BB52E50> [An established connection was aborted by the software in your host machine]. Retry 1/3 in 1.50 seconds
2024-11-11 12:54:56,335 ERROR:Error sending data to server: Cannot connect to host your-server-url.com:443 ssl:<ssl.SSLContext object at 0x000001FE7BB51D50> [An established connection was aborted by the software in your host machine]. Retry 2/3 in 2.25 seconds
2024-11-11 12:54:59,032 ERROR:Error sending data to server: Cannot connect to host your-server-url.com:443 ssl:<ssl.SSLContext object at 0x000001FE7BB538D0> [An established connection was aborted by the software in your host machine]. Retry 3/3 in 3.38 seconds
2024-11-11 12:55:02,411 CRITICAL:Max retries reached. Failed to send data
2024-11-11 12:55:16,428 ERROR:Error sending data to SharePoint
Traceback (most recent call last):
  File "C:\Users\David.Peter\AppData\Local\Programs\Python\Python312\Lib\site-packages\msal\authority.py", line 79, in __init__
    openid_config = tenant_discovery(
                    ^^^^^^^^^^^^^^^^^
  File "C:\Users\David.Peter\AppData\Local\Programs\Python\Python312\Lib\site-packages\msal\authority.py", line 216, in tenant_discovery
    raise ValueError("OIDC Discovery failed on {}. HTTP status: {}, Error: {}".format(
ValueError: OIDC Discovery failed on https://login.microsoftonline.com/your_tenant_id/v2.0/.well-known/openid-configuration. HTTP status: 400, Error: {"error":"invalid_tenant","error_description":"AADSTS90002: Tenant 'your_tenant_id' not found. Check to make sure you have the correct tenant ID and are signing into the correct cloud. Check with your subscription administrator, this may happen if there are no active subscriptions for the tenant. Trace ID: 07ef975e-e0e6-4486-9170-115d1de0aa01 Correlation ID: 839d90d1-89e5-4f8b-b5d2-c459099ebeb3 Timestamp: 2024-11-11 09:55:16Z","error_codes":[90002],"timestamp":"2024-11-11 09:55:16Z","trace_id":"07ef975e-e0e6-4486-9170-115d1de0aa01","correlation_id":"839d90d1-89e5-4f8b-b5d2-c459099ebeb3","error_uri":"https://login.microsoftonline.com/error?code=90002"}

During handling of the above exception, another exception occurred:

Traceback (most recent call last):
  File "C:\Users\David.Peter\Downloads\Softwares & Drivers\Scripts\System monitoring\agent.py", line 281, in send_data_to_sharepoint
    app = ConfidentialClientApplication(
          ^^^^^^^^^^^^^^^^^^^^^^^^^^^^^^
  File "C:\Users\David.Peter\AppData\Local\Programs\Python\Python312\Lib\site-packages\msal\application.py", line 608, in __init__
    self.authority = Authority(
                     ^^^^^^^^^^
  File "C:\Users\David.Peter\AppData\Local\Programs\Python\Python312\Lib\site-packages\msal\authority.py", line 95, in __init__
    raise ValueError(error_message)
ValueError: Unable to get authority configuration for https://login.microsoftonline.com/your_tenant_id. Authority would typically be in a format of https://login.microsoftonline.com/your_tenant or https://tenant_name.ciamlogin.com or https://tenant_name.b2clogin.com/tenant.onmicrosoft.com/policy.  Also please double check your tenant name or GUID is correct.
2024-11-11 12:55:16,807 ERROR:Error sending data to server: Cannot connect to host your-server-url.com:443 ssl:<ssl.SSLContext object at 0x000001FE7B87E2D0> [An established connection was aborted by the software in your host machine]. Retry 1/3 in 1.50 seconds
2024-11-11 12:55:18,765 ERROR:Error sending data to server: Cannot connect to host your-server-url.com:443 ssl:<ssl.SSLContext object at 0x000001FE7B8F6BD0> [An established connection was aborted by the software in your host machine]. Retry 2/3 in 2.25 seconds
2024-11-11 12:55:21,466 ERROR:Error sending data to server: Cannot connect to host your-server-url.com:443 ssl:<ssl.SSLContext object at 0x000001FE7BB51F50> [An established connection was aborted by the software in your host machine]. Retry 3/3 in 3.38 seconds
2024-11-11 12:55:24,844 CRITICAL:Max retries reached. Failed to send data
2024-11-11 12:55:39,062 ERROR:Error sending data to SharePoint
Traceback (most recent call last):
  File "C:\Users\David.Peter\AppData\Local\Programs\Python\Python312\Lib\site-packages\msal\authority.py", line 79, in __init__
    openid_config = tenant_discovery(
                    ^^^^^^^^^^^^^^^^^
  File "C:\Users\David.Peter\AppData\Local\Programs\Python\Python312\Lib\site-packages\msal\authority.py", line 216, in tenant_discovery
    raise ValueError("OIDC Discovery failed on {}. HTTP status: {}, Error: {}".format(
ValueError: OIDC Discovery failed on https://login.microsoftonline.com/your_tenant_id/v2.0/.well-known/openid-configuration. HTTP status: 400, Error: {"error":"invalid_tenant","error_description":"AADSTS90002: Tenant 'your_tenant_id' not found. Check to make sure you have the correct tenant ID and are signing into the correct cloud. Check with your subscription administrator, this may happen if there are no active subscriptions for the tenant. Trace ID: af9288a0-25de-4a62-804f-fd470db62900 Correlation ID: 76d02652-5afe-4984-aefa-d5f03cfe5304 Timestamp: 2024-11-11 09:55:38Z","error_codes":[90002],"timestamp":"2024-11-11 09:55:38Z","trace_id":"af9288a0-25de-4a62-804f-fd470db62900","correlation_id":"76d02652-5afe-4984-aefa-d5f03cfe5304","error_uri":"https://login.microsoftonline.com/error?code=90002"}

During handling of the above exception, another exception occurred:

Traceback (most recent call last):
  File "C:\Users\David.Peter\Downloads\Softwares & Drivers\Scripts\System monitoring\agent.py", line 281, in send_data_to_sharepoint
    app = ConfidentialClientApplication(
          ^^^^^^^^^^^^^^^^^^^^^^^^^^^^^^
  File "C:\Users\David.Peter\AppData\Local\Programs\Python\Python312\Lib\site-packages\msal\application.py", line 608, in __init__
    self.authority = Authority(
                     ^^^^^^^^^^
  File "C:\Users\David.Peter\AppData\Local\Programs\Python\Python312\Lib\site-packages\msal\authority.py", line 95, in __init__
    raise ValueError(error_message)
ValueError: Unable to get authority configuration for https://login.microsoftonline.com/your_tenant_id. Authority would typically be in a format of https://login.microsoftonline.com/your_tenant or https://tenant_name.ciamlogin.com or https://tenant_name.b2clogin.com/tenant.onmicrosoft.com/policy.  Also please double check your tenant name or GUID is correct.
2024-11-11 12:55:39,404 ERROR:Error sending data to server: Cannot connect to host your-server-url.com:443 ssl:<ssl.SSLContext object at 0x000001FE7BB531D0> [An established connection was aborted by the software in your host machine]. Retry 1/3 in 1.50 seconds
2024-11-11 12:55:41,399 ERROR:Error sending data to server: Cannot connect to host your-server-url.com:443 ssl:<ssl.SSLContext object at 0x000001FE7BAA9D50> [An established connection was aborted by the software in your host machine]. Retry 2/3 in 2.25 seconds
2024-11-11 12:55:44,473 ERROR:Error sending data to server: Cannot connect to host your-server-url.com:443 ssl:<ssl.SSLContext object at 0x000001FE7B87E2D0> [An established connection was aborted by the software in your host machine]. Retry 3/3 in 3.38 seconds
2024-11-11 12:55:47,864 CRITICAL:Max retries reached. Failed to send data
2024-11-11 12:56:02,398 ERROR:Error sending data to SharePoint
Traceback (most recent call last):
  File "C:\Users\David.Peter\AppData\Local\Programs\Python\Python312\Lib\site-packages\msal\authority.py", line 79, in __init__
    openid_config = tenant_discovery(
                    ^^^^^^^^^^^^^^^^^
  File "C:\Users\David.Peter\AppData\Local\Programs\Python\Python312\Lib\site-packages\msal\authority.py", line 216, in tenant_discovery
    raise ValueError("OIDC Discovery failed on {}. HTTP status: {}, Error: {}".format(
ValueError: OIDC Discovery failed on https://login.microsoftonline.com/your_tenant_id/v2.0/.well-known/openid-configuration. HTTP status: 400, Error: {"error":"invalid_tenant","error_description":"AADSTS90002: Tenant 'your_tenant_id' not found. Check to make sure you have the correct tenant ID and are signing into the correct cloud. Check with your subscription administrator, this may happen if there are no active subscriptions for the tenant. Trace ID: f4a42fea-5f9e-49bc-b95e-0d08eaae2500 Correlation ID: 73300721-17ea-49e1-ae02-3135bb3c5921 Timestamp: 2024-11-11 09:56:02Z","error_codes":[90002],"timestamp":"2024-11-11 09:56:02Z","trace_id":"f4a42fea-5f9e-49bc-b95e-0d08eaae2500","correlation_id":"73300721-17ea-49e1-ae02-3135bb3c5921","error_uri":"https://login.microsoftonline.com/error?code=90002"}

During handling of the above exception, another exception occurred:

Traceback (most recent call last):
  File "C:\Users\David.Peter\Downloads\Softwares & Drivers\Scripts\System monitoring\agent.py", line 281, in send_data_to_sharepoint
    app = ConfidentialClientApplication(
          ^^^^^^^^^^^^^^^^^^^^^^^^^^^^^^
  File "C:\Users\David.Peter\AppData\Local\Programs\Python\Python312\Lib\site-packages\msal\application.py", line 608, in __init__
    self.authority = Authority(
                     ^^^^^^^^^^
  File "C:\Users\David.Peter\AppData\Local\Programs\Python\Python312\Lib\site-packages\msal\authority.py", line 95, in __init__
    raise ValueError(error_message)
ValueError: Unable to get authority configuration for https://login.microsoftonline.com/your_tenant_id. Authority would typically be in a format of https://login.microsoftonline.com/your_tenant or https://tenant_name.ciamlogin.com or https://tenant_name.b2clogin.com/tenant.onmicrosoft.com/policy.  Also please double check your tenant name or GUID is correct.
2024-11-11 12:56:03,531 ERROR:Error sending data to server: Cannot connect to host your-server-url.com:443 ssl:<ssl.SSLContext object at 0x000001FE7BB53ED0> [An established connection was aborted by the software in your host machine]. Retry 1/3 in 1.50 seconds
2024-11-11 12:56:05,516 ERROR:Error sending data to server: Cannot connect to host your-server-url.com:443 ssl:<ssl.SSLContext object at 0x000001FE7BB52C50> [An established connection was aborted by the software in your host machine]. Retry 2/3 in 2.25 seconds
2024-11-11 12:56:08,339 ERROR:Error sending data to server: Cannot connect to host your-server-url.com:443 ssl:<ssl.SSLContext object at 0x000001FE7BB60DD0> [An established connection was aborted by the software in your host machine]. Retry 3/3 in 3.38 seconds
2024-11-11 12:56:11,722 CRITICAL:Max retries reached. Failed to send data
2024-11-11 12:56:19,271 INFO:Received signal to terminate. Shutting down gracefully...
2024-11-11 12:56:19,273 ERROR:An error occurred while running the main loop
Traceback (most recent call last):
  File "C:\Users\David.Peter\AppData\Local\Programs\Python\Python312\Lib\asyncio\runners.py", line 194, in run
    return runner.run(main)
           ^^^^^^^^^^^^^^^^
  File "C:\Users\David.Peter\AppData\Local\Programs\Python\Python312\Lib\asyncio\runners.py", line 118, in run
    return self._loop.run_until_complete(task)
           ^^^^^^^^^^^^^^^^^^^^^^^^^^^^^^^^^^^
  File "C:\Users\David.Peter\AppData\Local\Programs\Python\Python312\Lib\asyncio\base_events.py", line 687, in run_until_complete
    return future.result()
           ^^^^^^^^^^^^^^^
  File "C:\Users\David.Peter\Downloads\Softwares & Drivers\Scripts\System monitoring\agent.py", line 356, in main_loop
    await asyncio.sleep(INTERVAL)
  File "C:\Users\David.Peter\AppData\Local\Programs\Python\Python312\Lib\asyncio\tasks.py", line 665, in sleep
    return await future
           ^^^^^^^^^^^^
asyncio.exceptions.CancelledError

During handling of the above exception, another exception occurred:

Traceback (most recent call last):
  File "C:\Users\David.Peter\Downloads\Softwares & Drivers\Scripts\System monitoring\agent.py", line 394, in <module>
    asyncio.run(main_loop())
  File "C:\Users\David.Peter\AppData\Local\Programs\Python\Python312\Lib\asyncio\runners.py", line 193, in run
    with Runner(debug=debug, loop_factory=loop_factory) as runner:
  File "C:\Users\David.Peter\AppData\Local\Programs\Python\Python312\Lib\asyncio\runners.py", line 62, in __exit__
    self.close()
  File "C:\Users\David.Peter\AppData\Local\Programs\Python\Python312\Lib\asyncio\runners.py", line 72, in close
    loop.run_until_complete(
  File "C:\Users\David.Peter\AppData\Local\Programs\Python\Python312\Lib\asyncio\base_events.py", line 685, in run_until_complete
    raise RuntimeError('Event loop stopped before Future completed.')
RuntimeError: Event loop stopped before Future completed.
2024-11-11 12:56:19,292 INFO:Clinic server monitor shut down
